Workbook

Sheet _Seasonal-Products
A1: Fork Ranger Name | B1: common other names
A2: Abricot
A3: Apple
A4: Artichoke
A5: Asparagus
A6: Aubergine | B6: Eggplant
A7: Avocado
A8: Beetroot | B8: Beets
A9: Bell pepper | B9: Peppers
A10: Blackberry | B10: Brambles
A11: Blueberry
A12: Broad beans
A13: Broccoli
A14: Brussels sprouts
A15: Carrot
A16: Cauliflower
A17: Celery
A18: Cherry
A19: Chicory
A20: Chinese Cabbage | B20: Napa Cabbage
A21: Corn
A22: Cucumber
A23: Endive
A24: Fennel
A25: Fig
A26: Grapefruit | B26: Pummelo
A27: Grapes | B27: Muscadines
A28: Green bean | B28: Snap Bean
A29: Kale
A30: Kiwi
A31: Kohlrabi
A32: Leek
A33: Lettuce
A34: Loquat
A35: Mandarine | B35: Mandarin, Clementine, Tangerine
A36: Melon | B36: Cantaloupe
A37: Nectarine
A38: Orange
A39: Parsnip
A40: Peach
...

Sheet Alabama V
A1: vegetable | B1: Fork Ranger name | C1: helpcolumn | D1: January | E1: February | F1: March | G1: April | H1: May | I1: June | J1: July | K1: August | L1: September | M1: October | N1: November | O1: December
B2: Abricot | C2: =CONCATENATE(A2,B2) -> Abricot
A3: apples | B3: Apple | C3: =CONCATENATE(A3,B3) -> applesApple | J3: Starting Now | K3: Prime Time | L3: Prime Time | M3: Last Chance | P3: Alabama Seasonal Food Guide
A4: apples | B4: Apple | C4: =CONCATENATE(A4,B4) -> applesApple | L4: X | M4: X | N4: X | P4: Sweet Grown Alabama
A5: apples | B5: Apple | C5: =CONCATENATE(A5,B5) -> applesApple | J5: x | K5: x | L5: x | M5: x | P5: Farm Flavor Alabama
B6: Apple | C6: =CONCATENATE(A6,B6) -> Apple | J6: SN* | K6: PT* | L6: PT | M6: PT | N6: LC
B7: Artichoke | C7: =CONCATENATE(A7,B7) -> Artichoke
A8: asian-pears | B8: Asian pears | C8: =CONCATENATE(A8,B8) -> asian-pearsAsian pears | K8: Starting Now | L8: Prime Time | M8: Last Chance | P8: Alabama Seasonal Food Guide
B9: Asian pears | C9: =CONCATENATE(A9,B9) -> Asian pears
A10: asparagus | B10: Asparagus | C10: =CONCATENATE(A10,B10) -> asparagusAsparagus | F10: Starting Now | G10: Prime Time | H10: Prime Time | I10: Last Chance | P10: Alabama Seasonal Food Guide
B11: Asparagus | C11: =CONCATENATE(A11,B11) -> Asparagus | F11: SN- | G11: PT- | H11: PT- | I11: LC-
A12: eggplant | B12: Aubergine | C12: =CONCATENATE(A12,B12) -> eggplantAubergine | H12: Starting Now | I12: Prime Time | J12: Prime Time | K12: Prime Time | L12: Prime Time | M12: Last Chance | P12: Alabama Seasonal Food Guide
A13: eggplant | B13: Aubergine | C13: =CONCATENATE(A13,B13) -> eggplantAubergine | I13: x | J13: x | K13: x | L13: x | P13: Sweet Grown Alabama
A14: eggplant | B14: Aubergine | C14: =CONCATENATE(A14,B14) -> eggplantAubergine | H14: x | I14: x | J14: x | K14: x | L14: x | M14: x | P14: Farm Flavor Alabama
B15: Aubergine | C15: =CONCATENATE(A15,B15) -> Aubergine | H15: SN* | I15: PT | J15: PT | K15: PT | L15: PT | M15: LC*
B16: Avocado | C16: =CONCATENATE(A16,B16) -> Avocado
A17: beets | B17: Beetroot | C17: =CONCATENATE(A17,B17) -> beetsBeetroot | G17: Starting Now | H17: Prime Time | I17: Prime Time | J17: Last Chance | P17: Alabama Seasonal Food Guide
A18: beets | B18: Beetroot | C18: =CONCATENATE(A18,B18) -> beetsBeetroot | G18: x | H18: x | I18: x | J18: x | P18: Sweet Grown Alabama
A19: beets | B19: Beetroot | C19: =CONCATENATE(A19,B19) -> beetsBeetroot | G19: x | H19: x | I19: x | J19: x | P19: Farm Flavor Alabama
B20: Beetroot | C20: =CONCATENATE(A20,B20) -> Beetroot | G20: SN | H20: PT | I20: PT | J20: LC
A21: peppers | B21: Bell pepper | C21: =CONCATENATE(A21,B21) -> peppersBell pepper | I21: Starting Now | J21: Prime Time | K21: Prime Time | L21: Prime Time | M21: Last Chance | P21: Alabama Seasonal Food Guide
A22: bell pepper | B22: Bell pepper | C22: =CONCATENATE(A22,B22) -> bell pepperBell pepper | I22: x | J22: x | K22: x | L22: x | M22: x | P22: Sweet Grown Alabama
A23: Peppers | B23: Bell pepper | C23: =CONCATENATE(A23,B23) -> PeppersBell pepper | I23: x | J23: x | K23: x | L23: x | M23: x | P23: Farm Flavor Alabama
B24: Bell pepper | C24: =CONCATENATE(A24,B24) -> Bell pepper | I24: SN | J24: PT | K24: PT | L24: PT | M24: LC
A25: blackberries | B25: Blackberry | C25: =CONCATENATE(A25,B25) -> blackberriesBlackberry | I25: Starting Now | J25: Prime Time | K25: Prime Time | L25: Last Chance | P25: Alabama Seasonal Food Guide
A26: brambles | B26: Blackberry | C26: =CONCATENATE(A26,B26) -> bramblesBlackberry | I26: Starting Now | J26: Prime Time | K26: Prime Time | L26: Last Chance | P26: Alabama Seasonal Food Guide
A27: blackberries | B27: Blackberry | C27: =CONCATENATE(A27,B27) -> blackberriesBlackberry | J27: X | P27: Sweet Grown Alabama
A28: blackberries | B28: Blackberry | C28: =CONCATENATE(A28,B28) -> blackberriesBlackberry | I28: x | J28: x | K28: x | L28: x | P28: Farm Flavor Alabama
B29: Blackberry | C29: =CONCATENATE(A29,B29) -> Blackberry | I29: SN* | J29: PT | K29: PT* | L29: LC*
A30: blueberries | B30: Blueberry | C30: =CONCATENATE(A30,B30) -> blueberriesBlueberry | H30: Starting Now | I30: Prime Time | J30: Prime Time | K30: Last Chance | P30: Alabama Seasonal Food Guide
A31: blueberries | B31: Blueberry | C31: =CONCATENATE(A31,B31) -> blueberriesBlueberry | H31: X | I31: X | J31: X | P31: Sweet Grown Alabama
A32: blueberries | B32: Blueberry | C32: =CONCATENATE(A32,B32) -> blueberriesBlueberry | H32: x | I32: x | J32: x | K32: x | P32: Farm Flavor Alabama
B33: Blueberry | C33: =CONCATENATE(A33,B33) -> Blueberry | H33: SN | I33: PT | J33: PT | K33: LC*
A34: bok-choy | B34: Bok choy | C34: =CONCATENATE(A34,B34) -> bok-choyBok choy | G34: Starting Now | H34: Prime Time | I34: Prime Time | J34: Prime Time | K34: Prime Time | L34: Prime Time | M34: Last Chance | P34: Alabama Seasonal Food Guide
B35: Bok choy | C35: =CONCATENATE(A35,B35) -> Bok choy | G35: SN- | H35: PT- | I35: PT- | J35: PT- | K35: PT- | L35: PT- | M35: LC-
A36: boysenberries | B36: Boysenberry | C36: =CONCATENATE(A36,B36) -> boysenberriesBoysenberry | I36: Starting Now | J36: Prime Time | K36: Prime Time | L36: Last Chance | P36: Alabama Seasonal Food Guide
B37: Boysenberry | C37: =CONCATENATE(A37,B37) -> Boysenberry
B38: Broad beans | C38: =CONCATENATE(A38,B38) -> Broad beans
A39: broccoli | B39: Broccoli | C39: =CONCATENATE(A39,B39) -> broccoliBroccoli | H39: Starting Now | I39: Prime Time | J39: Prime Time | K39: Last Chance | P39: Alabama Seasonal Food Guide
A40: broccoli | B40: Broccoli | C40: =CONCATENATE(A40,B40) -> broccoliBroccoli | D40: x | E40: x | F40: x | N40: x | O40: x | P40: Sweet Grown Alabama
...

Sheet Georgia V
B1: Fork Ranger name | C1: Helpcolumn | D1: January | E1: February | F1: March | G1: April | H1: May | I1: June | J1: July | K1: August | L1: September | M1: October | N1: November | O1: December
A2: Apples | B2: Apple | C2: =CONCATENATE(A2,B2) -> ApplesApple | J2: Starting Now | K2: Prime Time | L2: Prime Time | M2: Prime Time | N2: Last Chance | P2: Georgia Farm Flavor
A3: Apples | B3: Apple | C3: =CONCATENATE(A3,B3) -> ApplesApple | J3: Starting Now | K3: Prime Time | L3: Prime Time | M3: Prime Time | N3: Last Chance | P3: Georgia Harvest Calendar
B4: Apple | C4: =CONCATENATE(A4,B4) -> Apple | J4: SN | K4: PT | L4: PT | M4: PT | N4: LC
A5: apples | B5: Apple | C5: =CONCATENATE(A5,B5) -> applesApple | J5: Starting Now | K5: Prime Time | L5: Prime Time | M5: Prime Time | N5: Last Chance | P5: Seasonal Food Guide
A6: asparagus | B6: Asparagus | C6: =CONCATENATE(A6,B6) -> asparagusAsparagus | F6: Starting Now | G6: Prime Time | H6: Prime Time | I6: Last Chance | P6: Seasonal Food Guide
B7: Asparagus | C7: =CONCATENATE(A7,B7) -> Asparagus | F7: SN- | G7: PT- | H7: PT- | I7: LC-
A8: Eggplant | B8: Aubergine | C8: =CONCATENATE(A8,B8) -> EggplantAubergine | I8: Starting Now | J8: Prime Time | K8: Prime Time | L8: Prime Time | M8: Last Chance | P8: Georgia Harvest Calendar
B9: Aubergine | C9: =CONCATENATE(A9,B9) -> Aubergine | I9: SN | J9: PT | K9: PT | L9: PT | M9: LC
A10: eggplant | B10: Aubergine | C10: =CONCATENATE(A10,B10) -> eggplantAubergine | I10: Starting Now | J10: Prime Time | K10: Prime Time | L10: Prime Time | M10: Last Chance | P10: Seasonal Food Guide
A11: beets | B11: Beetroot | C11: =CONCATENATE(A11,B11) -> beetsBeetroot | G11: Starting Now | H11: Prime Time | I11: Last Chance | P11: Seasonal Food Guide
B12: Beetroot | C12: =CONCATENATE(A12,B12) -> Beetroot | G12: SN- | H12: PT- | I12: LC-
A13: Bell Peppers | B13: Bell pepper | C13: =CONCATENATE(A13,B13) -> Bell PeppersBell pepper | J13: Starting Now | K13: Prime Time | L13: Prime Time | M13: Prime Time | N13: Last Chance | P13: Georgia Harvest Calendar
B14: Bell pepper | C14: =CONCATENATE(A14,B14) -> Bell pepper | I14: SN* | J14: PT | K14: PT | L14: PT | M14: LC* | N14: *
A15: Peppers | B15: Bell pepper | C15: =CONCATENATE(A15,B15) -> PeppersBell pepper | I15: Starting Now | J15: Prime Time | K15: Prime Time | L15: Last Chance | P15: Georgia Farm Flavor
A16: Peppers | B16: Bell pepper | C16: =CONCATENATE(A16,B16) -> PeppersBell pepper | J16: Starting Now | K16: Prime Time | L16: Prime Time | M16: Last Chance | P16: Georgia Harvest Calendar
A17: peppers | B17: Bell pepper | C17: =CONCATENATE(A17,B17) -> peppersBell pepper | I17: Starting Now | J17: Prime Time | K17: Prime Time | L17: Last Chance | P17: Seasonal Food Guide
A18: Blackberries | B18: Blackberry | C18: =CONCATENATE(A18,B18) -> BlackberriesBlackberry | I18: Starting Now | J18: Last Chance | P18: Georgia Farm Flavor
A19: Blackberries | B19: Blackberry | C19: =CONCATENATE(A19,B19) -> BlackberriesBlackberry | H19: Starting Now | I19: Prime Time | J19: Last Chance | P19: Georgia Harvest Calendar
B20: Blackberry | C20: =CONCATENATE(A20,B20) -> Blackberry | H20: * | I20: SN | J20: LC
A21: blackberries | B21: Blackberry | C21: =CONCATENATE(A21,B21) -> blackberriesBlackberry | I21: Starting Now | J21: Last Chance | P21: Seasonal Food Guide
A22: brambles | B22: Blackberry | C22: =CONCATENATE(A22,B22) -> bramblesBlackberry | I22: Starting Now | J22: Last Chance | P22: Seasonal Food Guide
A23: Blueberries | B23: Blueberry | C23: =CONCATENATE(A23,B23) -> BlueberriesBlueberry | I23: Starting Now | J23: Prime Time | K23: Last Chance | P23: Georgia Farm Flavor
A24: Blueberries | B24: Blueberry | C24: =CONCATENATE(A24,B24) -> BlueberriesBlueberry | H24: Starting Now | I24: Prime Time | J24: Prime Time | K24: Last Chance | P24: Georgia Harvest Calendar
B25: Blueberry | C25: =CONCATENATE(A25,B25) -> Blueberry | H25: * | I25: SN | J25: PT | K25: LC
A26: blueberries | B26: Blueberry | C26: =CONCATENATE(A26,B26) -> blueberriesBlueberry | I26: Starting Now | J26: Prime Time | K26: Last Chance | P26: Seasonal Food Guide
A27: bok-choy | B27: Bok choy | C27: =CONCATENATE(A27,B27) -> bok-choyBok choy | D27: Prime Time | E27: Prime Time | F27: Prime Time | G27: Prime Time | H27: Prime Time | I27: Last Chance | M27: Starting Now | N27: Prime Time | O27: Prime Time | P27: Seasonal Food Guide
B28: Bok choy | C28: =CONCATENATE(A28,B28) -> Bok choy | D28: PT- | E28: PT- | F28: PT- | G28: PT- | H28: PT- | I28: LC- | M28: SN- | N28: PT- | O28: PT-
A29: boysenberries | B29: Boysenberry | C29: =CONCATENATE(A29,B29) -> boysenberriesBoysenberry | I29: Starting Now | J29: Last Chance | P29: Seasonal Food Guide
A30: Broccoli | B30: Broccoli | C30: =CONCATENATE(A30,B30) -> BroccoliBroccoli | H30: Starting Now | I30: Last Chance | M30: Starting Now | N30: Prime Time | O30: Last Chance | P30: Georgia Harvest Calendar
B31: Broccoli | C31: =CONCATENATE(A31,B31) -> Broccoli | H31: SN | I31: LC | M31: SN | N31: PT | O31: LC
A32: broccoli | B32: Broccoli | C32: =CONCATENATE(A32,B32) -> broccoliBroccoli | H32: Starting Now | I32: Last Chance | M32: Starting Now | N32: Prime Time | O32: Last Chance | P32: Seasonal Food Guide
A33: Brussels Sprouts | B33: Brussels sprouts | C33: =CONCATENATE(A33,B33) -> Brussels SproutsBrussels sprouts | D33: Prime Time | E33: Last Chance | N33: Starting Now | O33: Prime Time | P33: Georgia Harvest Calendar
B34: Brussels sprouts | C34: =CONCATENATE(A34,B34) -> Brussels sprouts | D34: PT | E34: LC | N34: SN | O34: PT
A35: brussels-sprouts | B35: Brussels sprouts | C35: =CONCATENATE(A35,B35) -> brussels-sproutsBrussels sprouts | D35: Prime Time | E35: Last Chance | N35: Starting Now | O35: Prime Time | P35: Seasonal Food Guide
A36: cardoons | B36: Cardoons | C36: =CONCATENATE(A36,B36) -> cardoonsCardoons | M36: Starting Now | N36: Prime Time | O36: Last Chance | P36: Seasonal Food Guide
A37: Carrots | B37: Carrot | C37: =CONCATENATE(A37,B37) -> CarrotsCarrot | D37: Prime Time | E37: Prime Time | F37: Prime Time | G37: Prime Time | H37: Last Chance | M37: Starting Now | N37: Prime Time | O37: Prime Time | P37: Georgia Harvest Calendar
B38: Carrot | C38: =CONCATENATE(A38,B38) -> Carrot | D38: PT | E38: PT | F38: PT | G38: PT | H38: LC | I38: * | M38: SN | N38: PT | O38: PT
A39: carrots | B39: Carrot | C39: =CONCATENATE(A39,B39) -> carrotsCarrot | D39: Prime Time | E39: Prime Time | F39: Prime Time | G39: Prime Time | H39: Prime Time | I39: Last Chance | M39: Starting Now | N39: Prime Time | O39: Prime Time | P39: Seasonal Food Guide
A40: cauliflower | B40: Cauliflower | C40: =CONCATENATE(A40,B40) -> cauliflowerCauliflower | M40: Starting Now | N40: Prime Time | O40: Last Chance | P40: Seasonal Food Guide
...

Sheet Mississippi V
B1: Fork Ranger name | C1: helpcolumn | D1: January | E1: February | F1: March | G1: April | H1: May | I1: June | J1: July | K1: August | L1: September | M1: October | N1: November | O1: December
A2: Apples | B2: Apple | C2: =CONCATENATE(A2,B2) -> ApplesApple | H2: Starting Now | I2: Prime Time | J2: Last Chance | P2: Mississippi State University Extension Service
A3: apples | B3: Apple | C3: =CONCATENATE(A3,B3) -> applesApple | H3: Starting Now | I3: Prime Time | J3: Last Chance | P3: Seasonal Food Guide
B4: Apple | C4: =CONCATENATE(A4,B4) -> Apple | H4: SN | I4: PT | J4: LC
A5: asian-pears | B5: Asian pears | C5: =CONCATENATE(A5,B5) -> asian-pearsAsian pears | J5: Starting Now | K5: Prime Time | L5: Prime Time | M5: Last Chance | P5: Seasonal Food Guide
B6: Asian pears | C6: =CONCATENATE(A6,B6) -> Asian pears | J6: SN- | K6: PT- | L6: PT- | M6: LC-
A7: asparagus | B7: Asparagus | C7: =CONCATENATE(A7,B7) -> asparagusAsparagus | F7: Starting Now | G7: Prime Time | H7: Prime Time | I7: Last Chance | P7: Seasonal Food Guide
B8: Asparagus | C8: =CONCATENATE(A8,B8) -> Asparagus | F8: SN- | G8: PT- | H8: PT- | I8: LC-
A9: Eggplants | B9: Aubergine | C9: =CONCATENATE(A9,B9) -> EggplantsAubergine | I9: Starting Now | J9: Last Chance | P9: Mississippi State University Extension Service
A10: eggplant | B10: Aubergine | C10: =CONCATENATE(A10,B10) -> eggplantAubergine | I10: Starting Now | J10: Last Chance | P10: Seasonal Food Guide
B11: Aubergine | C11: =CONCATENATE(A11,B11) -> Aubergine | I11: SN | J11: PT
A12: beets | B12: Beetroot | C12: =CONCATENATE(A12,B12) -> beetsBeetroot | G12: Starting Now | H12: Prime Time | I12: Prime Time | J12: Last Chance | P12: Seasonal Food Guide
B13: Beetroot | C13: =CONCATENATE(A13,B13) -> Beetroot | G13: SN- | H13: PT- | I13: PT- | J13: LC-
A14: Bell Peppers | B14: Bell pepper | C14: =CONCATENATE(A14,B14) -> Bell PeppersBell pepper | I14: Starting Now | J14: Prime Time | K14: Last Chance | P14: Mississippi State University Extension Service
A15: peppers | B15: Bell pepper | C15: =CONCATENATE(A15,B15) -> peppersBell pepper | I15: Starting Now | J15: Prime Time | K15: Last Chance | P15: Seasonal Food Guide
B16: Bell pepper | C16: =CONCATENATE(A16,B16) -> Bell pepper | I16: SN | J16: PT | K16: LC
A17: blackberries | B17: Blackberry | C17: =CONCATENATE(A17,B17) -> blackberriesBlackberry | I17: Starting Now | J17: Prime Time | K17: Prime Time | L17: Last Chance | P17: Seasonal Food Guide
A18: brambles | B18: Blackberry | C18: =CONCATENATE(A18,B18) -> bramblesBlackberry | I18: Starting Now | J18: Prime Time | K18: Prime Time | L18: Last Chance | P18: Seasonal Food Guide
B19: Blackberry | C19: =CONCATENATE(A19,B19) -> Blackberry | I19: SN | J19: PT | K19: PT | L19: LC
A20: Blueberries | B20: Blueberry | C20: =CONCATENATE(A20,B20) -> BlueberriesBlueberry | H20: Starting Now | I20: Prime Time | J20: Last Chance | P20: Mississippi State University Extension Service
A21: blueberries | B21: Blueberry | C21: =CONCATENATE(A21,B21) -> blueberriesBlueberry | H21: Starting Now | I21: Prime Time | J21: Last Chance | P21: Seasonal Food Guide
B22: Blueberry | C22: =CONCATENATE(A22,B22) -> Blueberry | H22: SN | I22: PT | J22: LC
A23: bok-choy | B23: Bok choy | C23: =CONCATENATE(A23,B23) -> bok-choyBok choy | M23: Prime Time | P23: Seasonal Food Guide
B24: Bok choy | C24: =CONCATENATE(A24,B24) -> Bok choy | M24: PT-
A25: Broccoli | B25: Broccoli | C25: =CONCATENATE(A25,B25) -> BroccoliBroccoli | G25: Starting Now | H25: Prime Time | I25: Last Chance | M25: Starting Now | N25: Prime Time | O25: Last Chance | P25: Mississippi State University Extension Service
A26: broccoli | B26: Broccoli | C26: =CONCATENATE(A26,B26) -> broccoliBroccoli | G26: Starting Now | H26: Last Chance | M26: Starting Now | N26: Prime Time | O26: Last Chance | P26: Seasonal Food Guide
B27: Broccoli | C27: =CONCATENATE(A27,B27) -> Broccoli | G27: SN | H27: PT | I27: LC* | M27: SN | N27: PT | O27: LC
A28: brussels-sprouts | B28: Brussels sprouts | C28: =CONCATENATE(A28,B28) -> brussels-sproutsBrussels sprouts | M28: Starting Now | N28: Prime Time | O28: Last Chance | P28: Seasonal Food Guide
B29: Brussels sprouts | C29: =CONCATENATE(A29,B29) -> Brussels sprouts | M29: SN- | N29: PT- | O29: LC-
A30: cardoons | B30: Cardoons | C30: =CONCATENATE(A30,B30) -> cardoonsCardoons | M30: Starting Now | N30: Prime Time | O30: Last Chance | P30: Seasonal Food Guide
B31: Cardoons | C31: =CONCATENATE(A31,B31) -> Cardoons | M31: SN- | N31: PT- | O31: LC-
A32: carrots | B32: Carrot | C32: =CONCATENATE(A32,B32) -> carrotsCarrot | D32: Prime Time | E32: Prime Time | F32: Prime Time | G32: Prime Time | H32: Prime Time | I32: Prime Time | J32: Prime Time | K32: Prime Time | L32: Prime Time | M32: Prime Time | N32: Prime Time | O32: Prime Time | P32: Seasonal Food Guide
B33: Carrot | C33: =CONCATENATE(A33,B33) -> Carrot | D33: PT- | E33: PT- | F33: PT- | G33: PT- | H33: PT- | I33: PT- | J33: PT- | K33: PT- | L33: PT- | M33: PT- | N33: PT- | O33: PT-
A34: Cauliflower | B34: Cauliflower | C34: =CONCATENATE(A34,B34) -> CauliflowerCauliflower | G34: Starting Now | H34: Prime Time | I34: Last Chance | M34: Starting Now | N34: Prime Time | O34: Last Chance | P34: Mississippi State University Extension Service
A35: cauliflower | B35: Cauliflower | C35: =CONCATENATE(A35,B35) -> cauliflowerCauliflower | G35: Starting Now | H35: Last Chance | M35: Starting Now | N35: Prime Time | O35: Last Chance | P35: Seasonal Food Guide
B36: Cauliflower | C36: =CONCATENATE(A36,B36) -> Cauliflower | G36: SN | H36: PT | I36: LC* | M36: SN | N36: PT | O36: LC
A37: celery-root | B37: Celeriac | C37: =CONCATENATE(A37,B37) -> celery-rootCeleriac | D37: Prime Time | E37: Prime Time | F37: Prime Time | G37: Last Chance | N37: Starting Now | O37: Prime Time | P37: Seasonal Food Guide
B38: Celeriac | C38: =CONCATENATE(A38,B38) -> Celeriac | D38: PT- | E38: PT- | F38: PT- | G38: LC- | N38: SN- | O38: PT-
A39: celery | B39: Celery | C39: =CONCATENATE(A39,B39) -> celeryCelery | D39: Prime Time | E39: Prime Time | F39: Prime Time | G39: Last Chance | N39: Starting Now | O39: Prime Time | P39: Seasonal Food Guide
B40: Celery | C40: =CONCATENATE(A40,B40) -> Celery | D40: PT- | E40: PT- | F40: PT- | G40: LC- | N40: SN- | O40: PT-
...

Sheet North Carolina V
A1: vegetable | B1: Fork Ranger name | D1: January | E1: February | F1: March | G1: April | H1: May | I1: June | J1: July | K1: August | L1: September | M1: October | N1: November | O1: December
A2: apples | B2: Apple | C2: =CONCATENATE(A2,B2) -> applesApple | D2: Prime Time | E2: Last Chance | K2: Starting Now | L2: Prime Time | M2: Prime Time | N2: Prime Time | O2: Prime Time | P2: Seasonal Food Guide
A3: Apples | B3: Apple | C3: =CONCATENATE(A3,B3) -> ApplesApple | D3: Prime Time | E3: Last Chance | K3: Starting Now | L3: Prime Time | M3: Prime Time | N3: Prime Time | O3: Prime Time | P3: North Carolina State Source https://www.ncagr.gov/marketing/produce-availability-chart/open
B4: Apple | C4: =CONCATENATE(A4,B4) -> Apple | D4: PT | E4: LC | K4: SN | L4: PT | M4: PT | N4: PT | O4: PT
A5: asparagus | B5: Asparagus | C5: =CONCATENATE(A5,B5) -> asparagusAsparagus | F5: Starting Now | G5: Last Chance | P5: Seasonal Food Guide
A6: Asparagus | B6: Asparagus | C6: =CONCATENATE(A6,B6) -> AsparagusAsparagus | F6: Starting Now | G6: Last Chance | P6: North Carolina State Source https://www.ncagr.gov/marketing/produce-availability-chart/open
B7: Asparagus | C7: =CONCATENATE(A7,B7) -> Asparagus | F7: SN | G7: LC
A8: eggplant | B8: Aubergine | C8: =CONCATENATE(A8,B8) -> eggplantAubergine | I8: Starting Now | J8: Prime Time | K8: Last Chance | P8: Seasonal Food Guide
A9: Eggplant | B9: Aubergine | C9: =CONCATENATE(A9,B9) -> EggplantAubergine | I9: Starting Now | J9: Prime Time | K9: Last Chance | P9: North Carolina State Source https://www.ncagr.gov/marketing/produce-availability-chart/open
B10: Aubergine | C10: =CONCATENATE(A10,B10) -> Aubergine | I10: SN | J10: PT | K10: LC
A11: beets | B11: Beetroot | C11: =CONCATENATE(A11,B11) -> beetsBeetroot | H11: Starting Now | I11: Last Chance | M11: Starting Now | N11: Prime Time | O11: Last Chance | P11: Seasonal Food Guide
A12: Beets | B12: Beetroot | C12: =CONCATENATE(A12,B12) -> BeetsBeetroot | H12: Starting Now | I12: Last Chance | M12: Starting Now | N12: Prime Time | O12: Last Chance | P12: North Carolina State Source https://www.ncagr.gov/marketing/produce-availability-chart/open
B13: Beetroot | C13: =CONCATENATE(A13,B13) -> Beetroot | H13: SN | I13: LC | M13: SN | N13: PT | O13: LC
A14: peppers | B14: Bell pepper | C14: =CONCATENATE(A14,B14) -> peppersBell pepper | I14: Starting Now | J14: Prime Time | K14: Last Chance | P14: Seasonal Food Guide
A15: Peppers | B15: Bell pepper | C15: =CONCATENATE(A15,B15) -> PeppersBell pepper | I15: Starting Now | J15: Prime Time | K15: Last Chance | P15: North Carolina State Source https://www.ncagr.gov/marketing/produce-availability-chart/open
B16: Bell pepper | C16: =CONCATENATE(A16,B16) -> Bell pepper | I16: SN | J16: PT | K16: LC
A17: blackberries | B17: Blackberry | C17: =CONCATENATE(A17,B17) -> blackberriesBlackberry | I17: Starting Now | J17: Last Chance | L17: Prime Time | P17: Seasonal Food Guide
A18: brambles | B18: Blackberry | C18: =CONCATENATE(A18,B18) -> bramblesBlackberry | I18: Starting Now | J18: Last Chance | L18: Prime Time | P18: Seasonal Food Guide
A19: Blackberries | B19: Blackberry | C19: =CONCATENATE(A19,B19) -> BlackberriesBlackberry | I19: Starting Now | J19: Last Chance | L19: Prime Time | P19: North Carolina State Source https://www.ncagr.gov/marketing/produce-availability-chart/open
B20: Blackberry | C20: =CONCATENATE(A20,B20) -> Blackberry | I20: SN | J20: LC | K20: ? | L20: PT
A21: blueberries | B21: Blueberry | C21: =CONCATENATE(A21,B21) -> blueberriesBlueberry | H21: Starting Now | I21: Prime Time | J21: Last Chance | P21: Seasonal Food Guide
A22: Blueberries | B22: Blueberry | C22: =CONCATENATE(A22,B22) -> BlueberriesBlueberry | H22: Starting Now | I22: Prime Time | J22: Last Chance | P22: North Carolina State Source https://www.ncagr.gov/marketing/produce-availability-chart/open
B23: Blueberry | C23: =CONCATENATE(A23,B23) -> Blueberry | H23: SN | I23: PT | J23: LC
A24: bok-choy | B24: Bok choy | C24: =CONCATENATE(A24,B24) -> bok-choyBok choy | H24: Starting Now | I24: Last Chance | M24: Starting Now | N24: Prime Time | O24: Last Chance | P24: Seasonal Food Guide
A25: Bokchoy | B25: Bok choy | C25: =CONCATENATE(A25,B25) -> BokchoyBok choy | H25: Starting Now | I25: Last Chance | M25: Starting Now | N25: Prime Time | O25: Last Chance | P25: North Carolina State Source https://www.ncagr.gov/marketing/produce-availability-chart/open
B26: Bok choy | C26: =CONCATENATE(A26,B26) -> Bok choy | H26: SN | I26: LC | M26: SN | N26: PT | O26: LC
A27: broccoli | B27: Broccoli | C27: =CONCATENATE(A27,B27) -> broccoliBroccoli | G27: Starting Now | H27: Last Chance | P27: Seasonal Food Guide
A28: Broccoli | B28: Broccoli | C28: =CONCATENATE(A28,B28) -> BroccoliBroccoli | G28: Starting Now | H28: Last Chance | P28: North Carolina State Source https://www.ncagr.gov/marketing/produce-availability-chart/open
B29: Broccoli | C29: =CONCATENATE(A29,B29) -> Broccoli | G29: SN | H29: LC
A30: brussels-sprouts | B30: Brussels sprouts | C30: =CONCATENATE(A30,B30) -> brussels-sproutsBrussels sprouts | M30: Starting Now | N30: Prime Time | O30: Last Chance | P30: Seasonal Food Guide
B31: Brussels sprouts | C31: =CONCATENATE(A31,B31) -> Brussels sprouts | M31: SN- | N31: PT- | O31: LC-
A32: cardoons | B32: Cardoons | C32: =CONCATENATE(A32,B32) -> cardoonsCardoons | M32: Starting Now | N32: Prime Time | O32: Last Chance | P32: Seasonal Food Guide
B33: Cardoons | C33: =CONCATENATE(A33,B33) -> Cardoons | M33: SN- | N33: PT- | O33: LC-
A34: carrots | B34: Carrot | C34: =CONCATENATE(A34,B34) -> carrotsCarrot | D34: Last Chance | O34: Starting Now | P34: Seasonal Food Guide
A35: Carrots | B35: Carrot | C35: =CONCATENATE(A35,B35) -> CarrotsCarrot | D35: Last Chance | I35: Starting Now | J35: Last Chance | O35: Starting Now | P35: North Carolina State Source https://www.ncagr.gov/marketing/produce-availability-chart/open
B36: Carrot | C36: =CONCATENATE(A36,B36) -> Carrot | D36: LC | I36: SN* | J36: LC* | O36: SN
A37: cauliflower | B37: Cauliflower | C37: =CONCATENATE(A37,B37) -> cauliflowerCauliflower | M37: Starting Now | N37: Prime Time | O37: Last Chance | P37: Seasonal Food Guide
B38: Cauliflower | C38: =CONCATENATE(A38,B38) -> Cauliflower | M38: SN- | N38: PT- | O38: LC-
A39: celery-root | B39: Celeriac | C39: =CONCATENATE(A39,B39) -> celery-rootCeleriac | D39: Last Chance | M39: Starting Now | N39: Prime Time | O39: Prime Time | P39: Seasonal Food Guide
B40: Celeriac | C40: =CONCATENATE(A40,B40) -> Celeriac | D40: LC- | M40: SN- | N40: PT- | O40: PT-
...

Sheet South Carolina V
A1: vegetable | B1: Fork Ranger name | C1: helpcolumn | D1: January | E1: February | F1: March | G1: April | H1: May | I1: June | J1: July | K1: August | L1: September | M1: October | N1: November | O1: December
B2: Abricot | C2: =CONCATENATE(A2,B2) -> Abricot
A3: apples | B3: Apple | C3: =CONCATENATE(A3,B3) -> applesApple | L3: Starting Now | M3: Prime Time | N3: Prime Time | O3: Last Chance | P3: Seasonal Food Guide
A4: apples | B4: Apple | C4: =CONCATENATE(A4,B4) -> applesApple | L4: x | M4: x | N4: x | O4: x | P4: Certified South Carolina
B5: Apple | C5: =CONCATENATE(A5,B5) -> Apple | L5: SN | M5: PT | N5: PT | O5: LC
B6: Artichoke | C6: =CONCATENATE(A6,B6) -> Artichoke
B7: Asian pears | C7: =CONCATENATE(A7,B7) -> Asian pears
A8: asparagus | B8: Asparagus | C8: =CONCATENATE(A8,B8) -> asparagusAsparagus | F8: Starting Now | G8: Prime Time | H8: Last Chance | P8: Seasonal Food Guide
A9: asparagus | B9: Asparagus | C9: =CONCATENATE(A9,B9) -> asparagusAsparagus | F9: x | G9: x | H9: x | P9: Certified South Carolina
B10: Asparagus | C10: =CONCATENATE(A10,B10) -> Asparagus | F10: SN | G10: PT | H10: LC
A11: eggplant | B11: Aubergine | C11: =CONCATENATE(A11,B11) -> eggplantAubergine | I11: Starting Now | J11: Prime Time | K11: Prime Time | L11: Prime Time | M11: Last Chance | P11: Seasonal Food Guide
A12: eggplant | B12: Aubergine | C12: =CONCATENATE(A12,B12) -> eggplantAubergine | I12: x | J12: x | K12: x | N12: x | P12: Certified South Carolina
B13: Aubergine | C13: =CONCATENATE(A13,B13) -> Aubergine | I13: SN | J13: PT | K13: PT | L13: PT | M13: LC | N13: *
B14: Avocado | C14: =CONCATENATE(A14,B14) -> Avocado
A15: beets | B15: Beetroot | C15: =CONCATENATE(A15,B15) -> beetsBeetroot | D15: Prime Time | E15: Prime Time | F15: Prime Time | G15: Prime Time | H15: Prime Time | I15: Prime Time | J15: Prime Time | K15: Prime Time | L15: Prime Time | M15: Prime Time | N15: Prime Time | O15: Prime Time | P15: Seasonal Food Guide
A16: beets | B16: Beetroot | C16: =CONCATENATE(A16,B16) -> beetsBeetroot | D16: x | E16: x | F16: x | G16: x | H16: x | M16: x | N16: x | O16: x | P16: Certified South Carolina
B17: Beetroot | C17: =CONCATENATE(A17,B17) -> Beetroot | D17: PT | E17: PT | F17: PT | G17: PT | H17: PT | I17: GFS* | J17: GFS* | K17: GFS* | L17: GFS* | M17: PT | N17: PT | O17: PT
A18: peppers | B18: Bell pepper | C18: =CONCATENATE(A18,B18) -> peppersBell pepper | I18: Starting Now | J18: Prime Time | K18: Prime Time | L18: Prime Time | M18: Prime Time | N18: Last Chance | P18: Seasonal Food Guide
A19: peppers (variety) | B19: Bell pepper | C19: =CONCATENATE(A19,B19) -> peppers (variety)Bell pepper | I19: x | J19: x | K19: x | L19: x | M19: x | N19: x | P19: Certified South Carolina
B20: Bell pepper | C20: =CONCATENATE(A20,B20) -> Bell pepper | I20: SN | J20: PT | K20: PT | L20: PT | M20: PT | N20: LC
A21: blackberries | B21: Blackberry | C21: =CONCATENATE(A21,B21) -> blackberriesBlackberry | I21: Starting Now | J21: Last Chance | P21: Seasonal Food Guide
A22: brambles | B22: Blackberry | C22: =CONCATENATE(A22,B22) -> bramblesBlackberry | I22: Starting Now | J22: Last Chance | P22: Seasonal Food Guide
A23: blackberries | B23: Blackberry | C23: =CONCATENATE(A23,B23) -> blackberriesBlackberry | I23: x | J23: x | P23: Certified South Carolina
B24: Blackberry | C24: =CONCATENATE(A24,B24) -> Blackberry | I24: SN | J24: PT
A25: blueberries | B25: Blueberry | C25: =CONCATENATE(A25,B25) -> blueberriesBlueberry | I25: Starting Now | J25: Last Chance | P25: Seasonal Food Guide
A26: blueberries | B26: Blueberry | C26: =CONCATENATE(A26,B26) -> blueberriesBlueberry | G26: x | H26: x | I26: x | J26: x | P26: Certified South Carolina
B27: Blueberry | C27: =CONCATENATE(A27,B27) -> Blueberry | G27: * | H27: SN* | I27: PT | J27: LC
A28: bok-choy | B28: Bok choy | C28: =CONCATENATE(A28,B28) -> bok-choyBok choy | F28: Starting Now | G28: Prime Time | H28: Prime Time | I28: Last Chance | L28: Starting Now | M28: Last Chance | P28: Seasonal Food Guide
A29: bok choy | B29: Bok choy | C29: =CONCATENATE(A29,B29) -> bok choyBok choy | F29: x | G29: x | H29: x | I29: x | L29: x | M29: x | P29: Certified South Carolina
B30: Bok choy | C30: =CONCATENATE(A30,B30) -> Bok choy | F30: SN | G30: PT | H30: PT | I30: LC | L30: SN | M30: PT
B31: Boysenberry | C31: =CONCATENATE(A31,B31) -> Boysenberry
B32: Broad beans | C32: =CONCATENATE(A32,B32) -> Broad beans
A33: broccoli | B33: Broccoli | C33: =CONCATENATE(A33,B33) -> broccoliBroccoli | H33: Starting Now | I33: Prime Time | J33: Last Chance | M33: Starting Now | N33: Prime Time | O33: Last Chance | P33: Seasonal Food Guide
A34: broccoli | B34: Broccoli | C34: =CONCATENATE(A34,B34) -> broccoliBroccoli | G34: x | H34: x | I34: x | M34: x | N34: x | O34: x | P34: Certified South Carolina
B35: Broccoli | C35: =CONCATENATE(A35,B35) -> Broccoli | G35: * | H35: SN* | I35: PT | J35: LC* | M35: SN | N35: PT | O35: LC
A36: brussels-sprouts | B36: Brussels sprouts | C36: =CONCATENATE(A36,B36) -> brussels-sproutsBrussels sprouts | D36: Prime Time | E36: Last Chance | N36: Starting Now | O36: Prime Time | P36: Seasonal Food Guide
B37: Brussels sprouts | C37: =CONCATENATE(A37,B37) -> Brussels sprouts | D37: PT- | E37: LC- | N37: SN- | O37: PT-
A38: cantaloupe | B38: Cantaloupe | C38: =CONCATENATE(A38,B38) -> cantaloupeCantaloupe | I38: Starting Now | J38: Prime Time | K38: Last Chance | P38: Seasonal Food Guide
A39: cantaloupe | B39: Cantaloupe | C39: =CONCATENATE(A39,B39) -> cantaloupeCantaloupe | I39: x | J39: x | K39: x | P39: Certified South Carolina
B40: Cantaloupe | C40: =CONCATENATE(A40,B40) -> Cantaloupe | I40: SN | J40: PT | K40: LC
...

Sheet Tennessee V
A1: vegetable | B1: Fork Ranger name | C1: helpcolumn | D1: January | E1: February | F1: March | G1: April | H1: May | I1: June | J1: July | K1: August | L1: September | M1: October | N1: November | O1: December
A2: apricots | B2: Abricot | C2: =CONCATENATE(A2,B2) -> apricotsAbricot | J2: Starting Now | K2: Last Chance | P2: Seasonal Food Guide
B3: Abricot | C3: =CONCATENATE(A3,B3) -> Abricot | J3: SN- | K3: LC-
A4: apples | B4: Apple | C4: =CONCATENATE(A4,B4) -> applesApple | I4: Starting Now | J4: Prime Time | K4: Prime Time | L4: Prime Time | M4: Prime Time | N4: Last Chance | P4: Seasonal Food Guide
A5: Apples | B5: Apple | C5: =CONCATENATE(A5,B5) -> ApplesApple | I5: x | J5: x | K5: x | L5: x | M5: x | N5: x | O5: x | P5: University of Tennessee
A6: apples | B6: Apple | C6: =CONCATENATE(A6,B6) -> applesApple | I6: x | J6: x | K6: x | L6: x | M6: x | N6: x | P6: Tennessee Farm Flavor
B7: Apple | C7: =CONCATENATE(A7,B7) -> Apple | I7: SN | J7: PT | K7: PT | L7: PT | M7: PT | N7: PT | O7: LC*
A8: asian-pears | B8: Asian pears | C8: =CONCATENATE(A8,B8) -> asian-pearsAsian pears | K8: Starting Now | L8: Prime Time | M8: Last Chance | P8: Seasonal Food Guide
B9: Asian pears | C9: =CONCATENATE(A9,B9) -> Asian pears | K9: SN- | L9: PT- | M9: LC-
A10: asparagus | B10: Asparagus | C10: =CONCATENATE(A10,B10) -> asparagusAsparagus | G10: Starting Now | H10: Last Chance | P10: Seasonal Food Guide
A11: Asparagus | B11: Asparagus | C11: =CONCATENATE(A11,B11) -> AsparagusAsparagus | G11: x | H11: x | P11: University of Tennessee
A12: asparagus | B12: Asparagus | C12: =CONCATENATE(A12,B12) -> asparagusAsparagus | G12: x | H12: x | P12: Tennessee Farm Flavor
B13: Asparagus | C13: =CONCATENATE(A13,B13) -> Asparagus | G13: SN | H13: LC
A14: eggplant | B14: Aubergine | C14: =CONCATENATE(A14,B14) -> eggplantAubergine | J14: Starting Now | K14: Prime Time | L14: Last Chance | P14: Seasonal Food Guide
A15: Eggplant | B15: Aubergine | C15: =CONCATENATE(A15,B15) -> EggplantAubergine | J15: x | K15: x | L15: x | P15: University of Tennessee
A16: eggplants | B16: Aubergine | C16: =CONCATENATE(A16,B16) -> eggplantsAubergine | J16: x | K16: x | L16: x | P16: Tennessee Farm Flavor
B17: Aubergine | C17: =CONCATENATE(A17,B17) -> Aubergine | J17: SN | K17: PT | L17: LC
A18: beets | B18: Beetroot | C18: =CONCATENATE(A18,B18) -> beetsBeetroot | I18: Starting Now | J18: Prime Time | K18: Prime Time | L18: Prime Time | M18: Prime Time | N18: Last Chance | P18: Seasonal Food Guide
A19: beets | B19: Beetroot | C19: =CONCATENATE(A19,B19) -> beetsBeetroot | I19: x | J19: x | K19: x | L19: x | M19: x | N19: x | P19: Tennessee Farm Flavor
B20: Beetroot | C20: =CONCATENATE(A20,B20) -> Beetroot | I20: SN | J20: PT | K20: PT | L20: PT | M20: PT | N20: LC
A21: peppers | B21: Bell pepper | C21: =CONCATENATE(A21,B21) -> peppersBell pepper | J21: Starting Now | K21: Prime Time | L21: Prime Time | M21: Last Chance | P21: Seasonal Food Guide
A22: Bell Pepper | B22: Bell pepper | C22: =CONCATENATE(A22,B22) -> Bell PepperBell pepper | J22: x | K22: x | L22: x | M22: x | P22: University of Tennessee
A23: pimiento peppers | B23: Bell pepper | C23: =CONCATENATE(A23,B23) -> pimiento peppersBell pepper | J23: x | K23: x | L23: x | M23: x | P23: Tennessee Farm Flavor
A24: bell peppers | B24: Bell pepper | C24: =CONCATENATE(A24,B24) -> bell peppersBell pepper | J24: x | K24: x | L24: x | M24: x | P24: Tennessee Farm Flavor
B25: Bell pepper | C25: =CONCATENATE(A25,B25) -> Bell pepper | J25: SN | K25: PT | L25: PT | M25: LC
A26: blackberries | B26: Blackberry | C26: =CONCATENATE(A26,B26) -> blackberriesBlackberry | I26: Starting Now | J26: Prime Time | K26: Prime Time | L26: Last Chance | P26: Seasonal Food Guide
A27: brambles | B27: Blackberry | C27: =CONCATENATE(A27,B27) -> bramblesBlackberry | I27: Starting Now | J27: Prime Time | K27: Prime Time | L27: Last Chance | P27: Seasonal Food Guide
A28: blackberries | B28: Blackberry | C28: =CONCATENATE(A28,B28) -> blackberriesBlackberry | I28: x | J28: x | K28: x | L28: x | P28: Tennessee Farm Flavor
B29: Blackberry | C29: =CONCATENATE(A29,B29) -> Blackberry | I29: SN | J29: PT | K29: PT | L29: LC
A30: blueberries | B30: Blueberry | C30: =CONCATENATE(A30,B30) -> blueberriesBlueberry | I30: Starting Now | J30: Prime Time | K30: Last Chance | P30: Seasonal Food Guide
A31: Blueberries | B31: Blueberry | C31: =CONCATENATE(A31,B31) -> BlueberriesBlueberry | I31: x | J31: x | K31: x | P31: University of Tennessee
A32: blueberries | B32: Blueberry | C32: =CONCATENATE(A32,B32) -> blueberriesBlueberry | I32: x | J32: x | K32: x | P32: Tennessee Farm Flavor
B33: Blueberry | C33: =CONCATENATE(A33,B33) -> Blueberry | I33: SN | J33: PT | K33: LC
A34: bok-choy | B34: Bok choy | C34: =CONCATENATE(A34,B34) -> bok-choyBok choy | G34: Starting Now | H34: Prime Time | I34: Last Chance | M34: Starting Now | N34: Last Chance | P34: Seasonal Food Guide
A35: bok choy | B35: Bok choy | C35: =CONCATENATE(A35,B35) -> bok choyBok choy | G35: x | H35: x | I35: x | P35: Tennessee Farm Flavor
B36: Bok choy | C36: =CONCATENATE(A36,B36) -> Bok choy | G36: SN | H36: PT | I36: LC | M36: SN* | N36: LC*
A37: boysenberries | B37: Boysenberry | C37: =CONCATENATE(A37,B37) -> boysenberriesBoysenberry | I37: Starting Now | J37: Prime Time | K37: Last Chance | P37: Seasonal Food Guide
B38: Boysenberry | C38: =CONCATENATE(A38,B38) -> Boysenberry | I38: SN- | J38: PT- | K38: LC-
A39: broccoli | B39: Broccoli | C39: =CONCATENATE(A39,B39) -> broccoliBroccoli | G39: Starting Now | H39: Prime Time | I39: Last Chance | M39: Prime Time | P39: Seasonal Food Guide
A40: Broccoli | B40: Broccoli | C40: =CONCATENATE(A40,B40) -> BroccoliBroccoli | H40: x | I40: x | M40: x | N40: x | P40: University of Tennessee
...

Sheet Virginia V
A1: vegetable | B1: Fork Ranger name | C1: helpcolumn | D1: January | E1: February | F1: March | G1: April | H1: May | I1: June | J1: July | K1: August | L1: September | M1: October | N1: November | O1: December
A2: apples | B2: Apple | C2: =CONCATENATE(A2,B2) -> applesApple | D2: Prime Time | E2: Prime Time | F2: Prime Time | G2: Last Chance | J2: Starting Now | K2: Prime Time | L2: Prime Time | M2: Prime Time | N2: Prime Time | O2: Prime Time | P2: Virginia Seasonal Food Guide
A3: Apples | B3: Apple | C3: =CONCATENATE(A3,B3) -> ApplesApple | D3: Prime Time | E3: Prime Time | F3: Prime Time | G3: Last Chance | J3: Starting Now | K3: Prime Time | L3: Prime Time | M3: Prime Time | N3: Prime Time | O3: Prime Time | P3: Virginia State Source https://www.vdacs.virginia.gov/pdf/producechart.pdf
B4: Apple | C4: =CONCATENATE(A4,B4) -> Apple | D4: PT | E4: PT | F4: PT | G4: LC | J4: SN | K4: PT | L4: PT | M4: PT | N4: PT | O4: PT
A5: artichokes | B5: Artichoke | C5: =CONCATENATE(A5,B5) -> artichokesArtichoke | K5: Prime Time | P5: Virginia Seasonal Food Guide
B6: Artichoke | C6: =CONCATENATE(A6,B6) -> Artichoke | K6: PT-
A7: asian-pears | B7: Asian pears | C7: =CONCATENATE(A7,B7) -> asian-pearsAsian pears | K7: Starting Now | L7: Prime Time | M7: Prime Time | N7: Last Chance | P7: Virginia Seasonal Food Guide
A8: asian pears | B8: Asian pears | C8: =CONCATENATE(A8,B8) -> asian pearsAsian pears | K8: x | L8: x | M8: x | N8: x | P8: https://vagrown.vdacs.virginia.gov/whats-in-season
B9: Asian pears | C9: =CONCATENATE(A9,B9) -> Asian pears | K9: SN | L9: PT | M9: PT | N9: LC
A10: asparagus | B10: Asparagus | C10: =CONCATENATE(A10,B10) -> asparagusAsparagus | G10: Starting Now | H10: Prime Time | I10: Last Chance | P10: Virginia Seasonal Food Guide
A11: Asparagus | B11: Asparagus | C11: =CONCATENATE(A11,B11) -> AsparagusAsparagus | G11: Starting Now | H11: Prime Time | I11: Last Chance | P11: Virginia State Source https://www.vdacs.virginia.gov/pdf/producechart.pdf
B12: Asparagus | C12: =CONCATENATE(A12,B12) -> Asparagus | G12: SN | H12: PT | I12: LC
A13: eggplant | B13: Aubergine | C13: =CONCATENATE(A13,B13) -> eggplantAubergine | J13: Starting Now | K13: Prime Time | L13: Last Chance | P13: Virginia Seasonal Food Guide
A14: Eggplant | B14: Aubergine | C14: =CONCATENATE(A14,B14) -> EggplantAubergine | J14: Starting Now | K14: Prime Time | L14: Last Chance | P14: Virginia State Source https://www.vdacs.virginia.gov/pdf/producechart.pdf
B15: Aubergine | C15: =CONCATENATE(A15,B15) -> Aubergine | J15: SN | K15: PT | L15: LC
A16: beets | B16: Beetroot | C16: =CONCATENATE(A16,B16) -> beetsBeetroot | H16: Starting Now | I16: Prime Time | J16: Prime Time | K16: Prime Time | L16: Prime Time | M16: Prime Time | N16: Last Chance | P16: Virginia Seasonal Food Guide
A17: Beets | B17: Beetroot | C17: =CONCATENATE(A17,B17) -> BeetsBeetroot | H17: Starting Now | I17: Prime Time | J17: Prime Time | K17: Prime Time | L17: Prime Time | M17: Prime Time | N17: Last Chance | P17: Virginia State Source https://www.vdacs.virginia.gov/pdf/producechart.pdf
B18: Beetroot | C18: =CONCATENATE(A18,B18) -> Beetroot | H18: SN | I18: PT | J18: PT | K18: PT | L18: PT | M18: PT | N18: LC
A19: peppers | B19: Bell pepper | C19: =CONCATENATE(A19,B19) -> peppersBell pepper | J19: Starting Now | K19: Prime Time | L19: Prime Time | M19: Prime Time | N19: Last Chance | P19: Virginia Seasonal Food Guide
A20: Peppers | B20: Bell pepper | C20: =CONCATENATE(A20,B20) -> PeppersBell pepper | J20: Starting Now | K20: Prime Time | L20: Prime Time | M20: Prime Time | N20: Last Chance | P20: Virginia State Source https://www.vdacs.virginia.gov/pdf/producechart.pdf
B21: Bell pepper | C21: =CONCATENATE(A21,B21) -> Bell pepper | J21: SN | K21: PT | L21: PT | M21: PT | N21: LC
A22: blackberries | B22: Blackberry | C22: =CONCATENATE(A22,B22) -> blackberriesBlackberry | J22: Starting Now | K22: Last Chance | P22: Virginia Seasonal Food Guide
A23: brambles | B23: Blackberry | C23: =CONCATENATE(A23,B23) -> bramblesBlackberry | I23: Starting Now | J23: Prime Time | K23: Last Chance | P23: Virginia Seasonal Food Guide
A24: Blackberries | B24: Blackberry | C24: =CONCATENATE(A24,B24) -> BlackberriesBlackberry | I24: Starting Now | J24: Prime Time | K24: Last Chance | P24: Virginia State Source https://www.vdacs.virginia.gov/pdf/producechart.pdf
B25: Blackberry | C25: =CONCATENATE(A25,B25) -> Blackberry | I25: SN | J25: PT | K25: LC
A26: blueberries | B26: Blueberry | C26: =CONCATENATE(A26,B26) -> blueberriesBlueberry | I26: Starting Now | J26: Prime Time | K26: Last Chance | P26: Virginia Seasonal Food Guide
A27: Blueberries | B27: Blueberry | C27: =CONCATENATE(A27,B27) -> BlueberriesBlueberry | I27: Starting Now | J27: Prime Time | K27: Last Chance | P27: Virginia State Source https://www.vdacs.virginia.gov/pdf/producechart.pdf
B28: Blueberry | C28: =CONCATENATE(A28,B28) -> Blueberry | I28: SN | J28: PT | K28: LC
A29: bok-choy | B29: Bok choy | C29: =CONCATENATE(A29,B29) -> bok-choyBok choy | K29: Starting Now | L29: Prime Time | M29: Last Chance | P29: Virginia Seasonal Food Guide
B30: Bok choy | C30: =CONCATENATE(A30,B30) -> Bok choy | K30: SN- | L30: PT- | M30: LC-
A31: broccoli | B31: Broccoli | C31: =CONCATENATE(A31,B31) -> broccoliBroccoli | L31: Starting Now | M31: Prime Time | N31: Last Chance | P31: Virginia Seasonal Food Guide
A32: Broccoli | B32: Broccoli | C32: =CONCATENATE(A32,B32) -> BroccoliBroccoli | L32: Starting Now | M32: Prime Time | N32: Last Chance | P32: Virginia State Source https://www.vdacs.virginia.gov/pdf/producechart.pdf
B33: Broccoli | C33: =CONCATENATE(A33,B33) -> Broccoli | L33: SN | M33: PT | N33: LC
A34: brussels-sprouts | B34: Brussels sprouts | C34: =CONCATENATE(A34,B34) -> brussels-sproutsBrussels sprouts | M34: Starting Now | N34: Prime Time | O34: Last Chance | P34: Virginia Seasonal Food Guide
A35: brussels-sprouts | B35: Brussels sprouts | C35: =CONCATENATE(A35,B35) -> brussels-sproutsBrussels sprouts | M35: x | N35: x | O35: x | P35: https://vagrown.vdacs.virginia.gov/whats-in-season
B36: Brussels sprouts | C36: =CONCATENATE(A36,B36) -> Brussels sprouts | M36: SN | N36: PT | O36: LC
A37: cardoons | B37: Cardoons | C37: =CONCATENATE(A37,B37) -> cardoonsCardoons | M37: Starting Now | N37: Prime Time | O37: Last Chance | P37: Virginia Seasonal Food Guide
B38: Cardoons | C38: =CONCATENATE(A38,B38) -> Cardoons | M38: SN- | N38: PT- | O38: LC-
A39: carrots | B39: Carrot | C39: =CONCATENATE(A39,B39) -> carrotsCarrot | D39: Prime Time | E39: Prime Time | F39: Prime Time | G39: Prime Time | H39: Prime Time | I39: Prime Time | J39: Prime Time | K39: Prime Time | L39: Prime Time | M39: Prime Time | N39: Prime Time | O39: Prime Time | P39: Virginia Seasonal Food Guide
B40: Carrot | C40: =CONCATENATE(A40,B40) -> Carrot | D40: PT- | E40: PT- | F40: PT- | G40: PT- | H40: PT- | I40: PT- | J40: PT- | K40: PT- | L40: PT- | M40: PT- | N40: PT- | O40: PT-
...

Sheet West-Virginia V
A1: vegetable | B1: Fork Ranger name | C1: helpcolumn | D1: January | E1: February | F1: March | G1: April | H1: May | I1: June | J1: July | K1: August | L1: September | M1: October | N1: November | O1: December
A2: apricots | B2: Abricot | C2: =CONCATENATE(A2,B2) -> apricotsAbricot | J2: Starting Now | K2: Last Chance | P2: West-Virginia Seasonal Food Guide
B3: Abricot | C3: =CONCATENATE(A3,B3) -> Abricot | J3: SN- | K3: LC-
A4: apples | B4: Apple | C4: =CONCATENATE(A4,B4) -> applesApple | L4: Starting Now | M4: Last Chance | P4: West-Virginia Seasonal Food Guide
A5: apples | B5: Apple | C5: =CONCATENATE(A5,B5) -> applesApple | J5: x | K5: x | L5: x | M5: x | P5: Farm Flavor West-Virginia
B6: Apple | C6: =CONCATENATE(A6,B6) -> Apple | J6: * | K6: SN* | L6: PT | M6: LC
B7: Artichoke | C7: =CONCATENATE(A7,B7) -> Artichoke
A8: asian-pears | B8: Asian pears | C8: =CONCATENATE(A8,B8) -> asian-pearsAsian pears | K8: Starting Now | L8: Prime Time | M8: Last Chance | P8: West-Virginia Seasonal Food Guide
B9: Asian pears | C9: =CONCATENATE(A9,B9) -> Asian pears | K9: SN- | L9: PT- | M9: LC-
A10: asparagus | B10: Asparagus | C10: =CONCATENATE(A10,B10) -> asparagusAsparagus | H10: Starting Now | I10: Last Chance | P10: West-Virginia Seasonal Food Guide
B11: Asparagus | C11: =CONCATENATE(A11,B11) -> Asparagus | H11: SN- | I11: LC-
A12: eggplant | B12: Aubergine | C12: =CONCATENATE(A12,B12) -> eggplantAubergine | K12: Starting Now | L12: Prime Time | M12: Last Chance | P12: West-Virginia Seasonal Food Guide
A13: eggplant | B13: Aubergine | C13: =CONCATENATE(A13,B13) -> eggplantAubergine | J13: x | K13: x | L13: x | M13: x | P13: Farm Flavor West-Virginia
B14: Aubergine | C14: =CONCATENATE(A14,B14) -> Aubergine | J14: SN* | K14: PT | L14: PT | M14: LC
B15: Avocado | C15: =CONCATENATE(A15,B15) -> Avocado
A16: beets | B16: Beetroot | C16: =CONCATENATE(A16,B16) -> beetsBeetroot | K16: Starting Now | L16: Prime Time | M16: Last Chance | P16: West-Virginia Seasonal Food Guide
A17: beets | B17: Beetroot | C17: =CONCATENATE(A17,B17) -> beetsBeetroot | H17: x | I17: x | J17: x | K17: x | L17: x | M17: x | P17: Farm Flavor West-Virginia
B18: Beetroot | C18: =CONCATENATE(A18,B18) -> Beetroot | H18: * | I18: * | J18: SN* | K18: PT | L18: PT | M18: LC
A19: peppers | B19: Bell pepper | C19: =CONCATENATE(A19,B19) -> peppersBell pepper | J19: Starting Now | K19: Prime Time | L19: Prime Time | M19: Last Chance | P19: West-Virginia Seasonal Food Guide
A20: peppers | B20: Bell pepper | C20: =CONCATENATE(A20,B20) -> peppersBell pepper | I20: x | J20: x | K20: x | L20: x | P20: Farm Flavor West-Virginia
B21: Bell pepper | C21: =CONCATENATE(A21,B21) -> Bell pepper | I21: SN* | J21: PT | K21: PT | L21: PT | M21: LC*
A22: blackberries | B22: Blackberry | C22: =CONCATENATE(A22,B22) -> blackberriesBlackberry | J22: Starting Now | K22: Last Chance | P22: West-Virginia Seasonal Food Guide
A23: brambles | B23: Blackberry | C23: =CONCATENATE(A23,B23) -> bramblesBlackberry | J23: Starting Now | K23: Last Chance | P23: West-Virginia Seasonal Food Guide
A24: blackberries | B24: Blackberry | C24: =CONCATENATE(A24,B24) -> blackberriesBlackberry | J24: x | K24: x | P24: Farm Flavor West-Virginia
B25: Blackberry | C25: =CONCATENATE(A25,B25) -> Blackberry | J25: SN | K25: LC
A26: blueberries | B26: Blueberry | C26: =CONCATENATE(A26,B26) -> blueberriesBlueberry | J26: Starting Now | K26: Last Chance | P26: West-Virginia Seasonal Food Guide
A27: blueberries | B27: Blueberry | C27: =CONCATENATE(A27,B27) -> blueberriesBlueberry | J27: x | K27: x | P27: Farm Flavor West-Virginia
B28: Blueberry | C28: =CONCATENATE(A28,B28) -> Blueberry | J28: SN- | K28: LC-
A29: bok-choy | B29: Bok choy | C29: =CONCATENATE(A29,B29) -> bok-choyBok choy | K29: Prime Time | P29: West-Virginia Seasonal Food Guide
B30: Bok choy | C30: =CONCATENATE(A30,B30) -> Bok choy | K30: PT-
A31: boysenberries | B31: Boysenberry | C31: =CONCATENATE(A31,B31) -> boysenberriesBoysenberry | I31: Starting Now | J31: Last Chance | P31: West-Virginia Seasonal Food Guide
B32: Boysenberry | C32: =CONCATENATE(A32,B32) -> Boysenberry | I32: SN- | J32: LC-
B33: Broad beans | C33: =CONCATENATE(A33,B33) -> Broad beans
A34: broccoli | B34: Broccoli | C34: =CONCATENATE(A34,B34) -> broccoliBroccoli | I34: Starting Now | J34: Last Chance | P34: West-Virginia Seasonal Food Guide
A35: broccoli | B35: Broccoli | C35: =CONCATENATE(A35,B35) -> broccoliBroccoli | I35: x | J35: x | K35: x | L35: x | M35: x | P35: Farm Flavor West-Virginia
B36: Broccoli | C36: =CONCATENATE(A36,B36) -> Broccoli | I36: SN | J36: PT | K36: PT* | L36: PT* | M36: LC*
A37: brussels-sprouts | B37: Brussels sprouts | C37: =CONCATENATE(A37,B37) -> brussels-sproutsBrussels sprouts | L37: Starting Now | M37: Last Chance | P37: West-Virginia Seasonal Food Guide
B38: Brussels sprouts | C38: =CONCATENATE(A38,B38) -> Brussels sprouts | L38: SN- | M38: LC-
A39: cantaloupe | B39: Cantaloupe | C39: =CONCATENATE(A39,B39) -> cantaloupeCantaloupe | K39: Starting Now | L39: Prime Time | M39: Last Chance | P39: West-Virginia Seasonal Food Guide
A40: cantaloupe | B40: Cantaloupe | C40: =CONCATENATE(A40,B40) -> cantaloupeCantaloupe | K40: x | L40: x | P40: Farm Flavor West-Virginia
...

Sheet South-East
C1: 1 | D1: 2 | E1: 3 | F1: 4 | G1: 5 | H1: 6 | I1: 7 | J1: 8 | K1: 9 | L1: 10 | M1: 11 | N1: 12
A2: Abricot | B2: #VALUE! | C2: =VLOOKUP('South-East'!$A2,'Alabama V'!$C:$O,C$1+1,FALSE) -> 0 | D2: =VLOOKUP('South-East'!$A2,'Alabama V'!$C:$O,D$1+1,FALSE) -> 0 | E2: =VLOOKUP('South-East'!$A2,'Alabama V'!$C:$O,E$1+1,FALSE) -> 0 | F2: =VLOOKUP('South-East'!$A2,'Alabama V'!$C:$O,F$1+1,FALSE) -> 0 | G2: =VLOOKUP('South-East'!$A2,'Alabama V'!$C:$O,G$1+1,FALSE) -> 0 | H2: =VLOOKUP('South-East'!$A2,'Alabama V'!$C:$O,H$1+1,FALSE) -> 0 | I2: =VLOOKUP('South-East'!$A2,'Alabama V'!$C:$O,I$1+1,FALSE) -> 0 | J2: =VLOOKUP('South-East'!$A2,'Alabama V'!$C:$O,J$1+1,FALSE) -> 0 | ... N2: =VLOOKUP('South-East'!$A2,'Alabama V'!$C:$O,N$1+1,FALSE) -> 0 | O2: If we would group them, then no abricots (90% in California: https://www.ers.usda.gov/data-products/charts-of-note/chart-detail?chartId=108213)
A3: Abricot | B3: #VALUE! | C3: =VLOOKUP('South-East'!$A2,'Georgia V'!$C:$O,C$1+1,FALSE) -> #N/A | D3: =VLOOKUP('South-East'!$A2,'Georgia V'!$C:$O,D$1+1,FALSE) -> #N/A | E3: =VLOOKUP('South-East'!$A2,'Georgia V'!$C:$O,E$1+1,FALSE) -> #N/A | F3: =VLOOKUP('South-East'!$A2,'Georgia V'!$C:$O,F$1+1,FALSE) -> #N/A | G3: =VLOOKUP('South-East'!$A2,'Georgia V'!$C:$O,G$1+1,FALSE) -> #N/A | H3: =VLOOKUP('South-East'!$A2,'Georgia V'!$C:$O,H$1+1,FALSE) -> #N/A | I3: =VLOOKUP('South-East'!$A2,'Georgia V'!$C:$O,I$1+1,FALSE) -> #N/A | J3: =VLOOKUP('South-East'!$A2,'Georgia V'!$C:$O,J$1+1,FALSE) -> #N/A | ... N3: =VLOOKUP('South-East'!$A2,'Georgia V'!$C:$O,N$1+1,FALSE) -> #N/A
A4: Abricot | B4: #VALUE! | C4: =VLOOKUP('South-East'!$A2,'Mississippi V'!$C:$O,C$1+1,FALSE) -> #N/A | D4: =VLOOKUP('South-East'!$A2,'Mississippi V'!$C:$O,D$1+1,FALSE) -> #N/A | E4: =VLOOKUP('South-East'!$A2,'Mississippi V'!$C:$O,E$1+1,FALSE) -> #N/A | F4: =VLOOKUP('South-East'!$A2,'Mississippi V'!$C:$O,F$1+1,FALSE) -> #N/A | G4: =VLOOKUP('South-East'!$A2,'Mississippi V'!$C:$O,G$1+1,FALSE) -> #N/A | H4: =VLOOKUP('South-East'!$A2,'Mississippi V'!$C:$O,H$1+1,FALSE) -> #N/A | I4: =VLOOKUP('South-East'!$A2,'Mississippi V'!$C:$O,I$1+1,FALSE) -> #N/A | J4: =VLOOKUP('South-East'!$A2,'Mississippi V'!$C:$O,J$1+1,FALSE) -> #N/A | ... N4: =VLOOKUP('South-East'!$A2,'Mississippi V'!$C:$O,N$1+1,FALSE) -> #N/A
A5: Abricot | B5: #VALUE! | C5: =VLOOKUP('South-East'!$A2,'North Carolina V'!$C:$O,C$1+1,FALSE) -> #N/A | D5: =VLOOKUP('South-East'!$A2,'North Carolina V'!$C:$O,D$1+1,FALSE) -> #N/A | E5: =VLOOKUP('South-East'!$A2,'North Carolina V'!$C:$O,E$1+1,FALSE) -> #N/A | F5: =VLOOKUP('South-East'!$A2,'North Carolina V'!$C:$O,F$1+1,FALSE) -> #N/A | G5: =VLOOKUP('South-East'!$A2,'North Carolina V'!$C:$O,G$1+1,FALSE) -> #N/A | H5: =VLOOKUP('South-East'!$A2,'North Carolina V'!$C:$O,H$1+1,FALSE) -> #N/A | I5: =VLOOKUP('South-East'!$A2,'North Carolina V'!$C:$O,I$1+1,FALSE) -> #N/A | J5: =VLOOKUP('South-East'!$A2,'North Carolina V'!$C:$O,J$1+1,FALSE) -> #N/A | ... N5: =VLOOKUP('South-East'!$A2,'North Carolina V'!$C:$O,N$1+1,FALSE) -> #N/A
A6: Abricot | B6: #VALUE! | C6: =VLOOKUP('South-East'!$A2,'South Carolina V'!$C:$O,C$1+1,FALSE) -> 0 | D6: =VLOOKUP('South-East'!$A2,'South Carolina V'!$C:$O,D$1+1,FALSE) -> 0 | E6: =VLOOKUP('South-East'!$A2,'South Carolina V'!$C:$O,E$1+1,FALSE) -> 0 | F6: =VLOOKUP('South-East'!$A2,'South Carolina V'!$C:$O,F$1+1,FALSE) -> 0 | G6: =VLOOKUP('South-East'!$A2,'South Carolina V'!$C:$O,G$1+1,FALSE) -> 0 | H6: =VLOOKUP('South-East'!$A2,'South Carolina V'!$C:$O,H$1+1,FALSE) -> 0 | I6: =VLOOKUP('South-East'!$A2,'South Carolina V'!$C:$O,I$1+1,FALSE) -> 0 | J6: =VLOOKUP('South-East'!$A2,'South Carolina V'!$C:$O,J$1+1,FALSE) -> 0 | ... N6: =VLOOKUP('South-East'!$A2,'South Carolina V'!$C:$O,N$1+1,FALSE) -> 0
A7: Abricot | B7: #VALUE! | C7: =VLOOKUP('South-East'!$A2,'Tennessee V'!$C:$O,C$1+1,FALSE) -> 0 | D7: =VLOOKUP('South-East'!$A2,'Tennessee V'!$C:$O,D$1+1,FALSE) -> 0 | E7: =VLOOKUP('South-East'!$A2,'Tennessee V'!$C:$O,E$1+1,FALSE) -> 0 | F7: =VLOOKUP('South-East'!$A2,'Tennessee V'!$C:$O,F$1+1,FALSE) -> 0 | G7: =VLOOKUP('South-East'!$A2,'Tennessee V'!$C:$O,G$1+1,FALSE) -> 0 | H7: =VLOOKUP('South-East'!$A2,'Tennessee V'!$C:$O,H$1+1,FALSE) -> 0 | I7: =VLOOKUP('South-East'!$A2,'Tennessee V'!$C:$O,I$1+1,FALSE) -> SN- | J7: =VLOOKUP('South-East'!$A2,'Tennessee V'!$C:$O,J$1+1,FALSE) -> LC- | ... N7: =VLOOKUP('South-East'!$A2,'Tennessee V'!$C:$O,N$1+1,FALSE) -> 0 | O7: Could be available in the Appalacchian Mountains but not further south
A8: Abricot | B8: #VALUE! | C8: =VLOOKUP('South-East'!$A2,'Virginia V'!$C:$O,C$1+1,FALSE) -> #N/A | D8: =VLOOKUP('South-East'!$A2,'Virginia V'!$C:$O,D$1+1,FALSE) -> #N/A | E8: =VLOOKUP('South-East'!$A2,'Virginia V'!$C:$O,E$1+1,FALSE) -> #N/A | F8: =VLOOKUP('South-East'!$A2,'Virginia V'!$C:$O,F$1+1,FALSE) -> #N/A | G8: =VLOOKUP('South-East'!$A2,'Virginia V'!$C:$O,G$1+1,FALSE) -> #N/A | H8: =VLOOKUP('South-East'!$A2,'Virginia V'!$C:$O,H$1+1,FALSE) -> #N/A | I8: =VLOOKUP('South-East'!$A2,'Virginia V'!$C:$O,I$1+1,FALSE) -> #N/A | J8: =VLOOKUP('South-East'!$A2,'Virginia V'!$C:$O,J$1+1,FALSE) -> #N/A | ... N8: =VLOOKUP('South-East'!$A2,'Virginia V'!$C:$O,N$1+1,FALSE) -> #N/A
A9: Abricot | B9: #VALUE! | C9: =VLOOKUP('South-East'!$A2,'West-Virginia V'!$C:$O,C$1+1,FALSE) -> 0 | D9: =VLOOKUP('South-East'!$A2,'West-Virginia V'!$C:$O,D$1+1,FALSE) -> 0 | E9: =VLOOKUP('South-East'!$A2,'West-Virginia V'!$C:$O,E$1+1,FALSE) -> 0 | F9: =VLOOKUP('South-East'!$A2,'West-Virginia V'!$C:$O,F$1+1,FALSE) -> 0 | G9: =VLOOKUP('South-East'!$A2,'West-Virginia V'!$C:$O,G$1+1,FALSE) -> 0 | H9: =VLOOKUP('South-East'!$A2,'West-Virginia V'!$C:$O,H$1+1,FALSE) -> 0 | I9: =VLOOKUP('South-East'!$A2,'West-Virginia V'!$C:$O,I$1+1,FALSE) -> SN- | J9: =VLOOKUP('South-East'!$A2,'West-Virginia V'!$C:$O,J$1+1,FALSE) -> LC- | ... N9: =VLOOKUP('South-East'!$A2,'West-Virginia V'!$C:$O,N$1+1,FALSE) -> 0
A10: Abricot | B10: South-East | C10: 0 | D10: 0 | E10: 0 | F10: 0 | G10: 0 | H10: 0 | I10: 0 | J10: 0 | K10: 0 | L10: 0 | M10: 0 | N10: 0
A11: Apple | B11: #VALUE! | C11: =VLOOKUP('South-East'!$A11,'Alabama V'!$C:$O,C$1+1,FALSE) -> 0 | D11: =VLOOKUP('South-East'!$A11,'Alabama V'!$C:$O,D$1+1,FALSE) -> 0 | E11: =VLOOKUP('South-East'!$A11,'Alabama V'!$C:$O,E$1+1,FALSE) -> 0 | F11: =VLOOKUP('South-East'!$A11,'Alabama V'!$C:$O,F$1+1,FALSE) -> 0 | G11: =VLOOKUP('South-East'!$A11,'Alabama V'!$C:$O,G$1+1,FALSE) -> 0 | H11: =VLOOKUP('South-East'!$A11,'Alabama V'!$C:$O,H$1+1,FALSE) -> 0 | I11: =VLOOKUP('South-East'!$A11,'Alabama V'!$C:$O,I$1+1,FALSE) -> SN* | J11: =VLOOKUP('South-East'!$A11,'Alabama V'!$C:$O,J$1+1,FALSE) -> PT* | ... N11: =VLOOKUP('South-East'!$A11,'Alabama V'!$C:$O,N$1+1,FALSE) -> 0 | O11: Are apples also available later in Mississippi? (Here: June to October https://happyhealthy.extension.msstate.edu/fact-sheets/happyhealthy-apples-fact-sheet, https://extension.msstate.edu/publications/buy-fresh-fruits-and-vegetables-season)
A12: Apple | B12: #VALUE! | C12: =VLOOKUP('South-East'!$A11,'Georgia V'!$C:$O,C$1+1,FALSE) -> 0 | D12: =VLOOKUP('South-East'!$A11,'Georgia V'!$C:$O,D$1+1,FALSE) -> 0 | E12: =VLOOKUP('South-East'!$A11,'Georgia V'!$C:$O,E$1+1,FALSE) -> 0 | F12: =VLOOKUP('South-East'!$A11,'Georgia V'!$C:$O,F$1+1,FALSE) -> 0 | G12: =VLOOKUP('South-East'!$A11,'Georgia V'!$C:$O,G$1+1,FALSE) -> 0 | H12: =VLOOKUP('South-East'!$A11,'Georgia V'!$C:$O,H$1+1,FALSE) -> 0 | I12: =VLOOKUP('South-East'!$A11,'Georgia V'!$C:$O,I$1+1,FALSE) -> SN | J12: =VLOOKUP('South-East'!$A11,'Georgia V'!$C:$O,J$1+1,FALSE) -> PT | ... N12: =VLOOKUP('South-East'!$A11,'Georgia V'!$C:$O,N$1+1,FALSE) -> 0
A13: Apple | B13: #VALUE! | C13: =VLOOKUP('South-East'!$A11,'Mississippi V'!$C:$O,C$1+1,FALSE) -> 0 | D13: =VLOOKUP('South-East'!$A11,'Mississippi V'!$C:$O,D$1+1,FALSE) -> 0 | E13: =VLOOKUP('South-East'!$A11,'Mississippi V'!$C:$O,E$1+1,FALSE) -> 0 | F13: =VLOOKUP('South-East'!$A11,'Mississippi V'!$C:$O,F$1+1,FALSE) -> 0 | G13: =VLOOKUP('South-East'!$A11,'Mississippi V'!$C:$O,G$1+1,FALSE) -> SN | H13: =VLOOKUP('South-East'!$A11,'Mississippi V'!$C:$O,H$1+1,FALSE) -> PT | I13: =VLOOKUP('South-East'!$A11,'Mississippi V'!$C:$O,I$1+1,FALSE) -> LC | J13: =VLOOKUP('South-East'!$A11,'Mississippi V'!$C:$O,J$1+1,FALSE) -> 0 | ... N13: =VLOOKUP('South-East'!$A11,'Mississippi V'!$C:$O,N$1+1,FALSE) -> 0
A14: Apple | B14: #VALUE! | C14: =VLOOKUP('South-East'!$A11,'North Carolina V'!$C:$O,C$1+1,FALSE) -> PT | D14: =VLOOKUP('South-East'!$A11,'North Carolina V'!$C:$O,D$1+1,FALSE) -> LC | E14: =VLOOKUP('South-East'!$A11,'North Carolina V'!$C:$O,E$1+1,FALSE) -> 0 | F14: =VLOOKUP('South-East'!$A11,'North Carolina V'!$C:$O,F$1+1,FALSE) -> 0 | G14: =VLOOKUP('South-East'!$A11,'North Carolina V'!$C:$O,G$1+1,FALSE) -> 0 | H14: =VLOOKUP('South-East'!$A11,'North Carolina V'!$C:$O,H$1+1,FALSE) -> 0 | I14: =VLOOKUP('South-East'!$A11,'North Carolina V'!$C:$O,I$1+1,FALSE) -> 0 | J14: =VLOOKUP('South-East'!$A11,'North Carolina V'!$C:$O,J$1+1,FALSE) -> SN | ... N14: =VLOOKUP('South-East'!$A11,'North Carolina V'!$C:$O,N$1+1,FALSE) -> PT
A15: Apple | B15: #VALUE! | C15: =VLOOKUP('South-East'!$A11,'South Carolina V'!$C:$O,C$1+1,FALSE) -> 0 | D15: =VLOOKUP('South-East'!$A11,'South Carolina V'!$C:$O,D$1+1,FALSE) -> 0 | E15: =VLOOKUP('South-East'!$A11,'South Carolina V'!$C:$O,E$1+1,FALSE) -> 0 | F15: =VLOOKUP('South-East'!$A11,'South Carolina V'!$C:$O,F$1+1,FALSE) -> 0 | G15: =VLOOKUP('South-East'!$A11,'South Carolina V'!$C:$O,G$1+1,FALSE) -> 0 | H15: =VLOOKUP('South-East'!$A11,'South Carolina V'!$C:$O,H$1+1,FALSE) -> 0 | I15: =VLOOKUP('South-East'!$A11,'South Carolina V'!$C:$O,I$1+1,FALSE) -> 0 | J15: =VLOOKUP('South-East'!$A11,'South Carolina V'!$C:$O,J$1+1,FALSE) -> 0 | ... N15: =VLOOKUP('South-East'!$A11,'South Carolina V'!$C:$O,N$1+1,FALSE) -> LC
